Workbook

Sheet 00_README
A1: CGI-AIG-001 | B1: AI Governance Assessment - EU AI Act applicability and ISO/IEC 42001 gap assessment
A2: Organisation | B2: Cypher Group Inc. (SIMULATED) - 50 employees, B2B SaaS project-management platform, ~200 SMB customers, ~USD 3.6M ARR
A3: CASE STUDY NOTICE | B3: Simulated case study. Laws, standards, article and clause numbers are real and current to 17 Oct 2026; ISO/IEC 42001 wording is paraphrased.
A4: Laws and standards | B4: Regulation (EU) 2024/1689 (AI Act) as amended by Regulation (EU) 2026/1744 (Digital Omnibus on AI); ISO/IEC 42001:2023; NIST AI RMF 1.0; GDPR
A5: Assessment date | B5: 17 October 2026
A6: Prepared by | B6: O.S (assessor)
A7: Approving authority | B7: Jerry Gold, Chief Executive Officer
A8: Status | B8: Draft for approval
A9: Colour key | B9: Yellow = assessor input (change it and every score recalculates). Grey = formula. Navy = header.
A10: How to use | B10: Change a maturity in 05_Annex_A or a score in 04_Clauses and watch 06_Readiness and 19_Issue_Checklist update.
A11: Sheets | B11: 01 register · 02 AI Act tests · 03 timeline · 04 clauses · 05 Annex A · 06 readiness · 07 impact assessments · 08 harm scores · 09 DPIA screening · 10 findings · 11 severity rule · 12 mapping · 13 drawer-2 test · 14 register v1.3 · 15 roadmap · 16 conflicts · 17 maturity · 18 assumptions · 19 issue checklist

Sheet 01_AI_Register
A1: Part 2 - AI system register. Built only from what Projects 01-07 record, plus scenario AI-A01.
A3: AI system ID | B3: AI system | C3: Supplier (ID) | D3: What it does | E3: Status on 17 Oct 2026 | F3: How it entered Cypher | G3: Business owner (job title) | H3: Scale | I3: Data in | J3: Data out | K3: Classification (CGI-POL-004) | L3: People affected | M3: Cypher's AI Act role | N3: Role article | O3: Risk tier for Cypher | P3: Deciding article(s) | Q3: Duties that sit with the provider, not Cypher | R3: Model training on Cypher content (VQ-68) | S3: GDPR Art. 28 DPA (CGI-TPR-001) | T3: Human oversight today | U3: Source in earlier projects | V3: Related risk IDs | W3: Related findings | X3: Impact-assessment triage rank
A4: AIS-01 | B4: ScribeCo meeting assistant | C4: ScribeCo (CGI-VEN-012) | D4: Joins internal and customer calls, records audio, produces transcripts and summaries | E4: In use. Shadow AI found 15 Sep 2026 in the expense review; CGI-TPR-001 decision was due 15 Oct 2026 and none is recorded | F4: Bought on a personal card; never onboarded (discovery source 2, finance) | G4: Head of Customer Success | H4: About 40 meetings a month | I4: Full audio of internal and customer calls: voices, names, commercial and security discussion, any personal data spoken aloud | J4: Transcripts, summaries, action items | K4: Confidential | L4: Customer staff on calls; Cypher staff; third parties named in calls | M4: Deployer | N4: Art. 3(4) | O4: Minimal (no AI Act duty beyond Art. 4 and Art. 5) | P4: Art. 6(2) + Annex III (no listed use); Art. 5(1)(f) checked (see AI-A02); Art. 50(3)-(4) not triggered | Q4: Art. 50(1) disclosure if the bot is intended to interact with people; Art. 50(2) marking of generated text | R4: Unknown: no contract, terms never reviewed | S4: None: no contract of any kind | T4: None recorded. CGI-POL-001 s4.5.3 requires review before output reaches a customer | U4: CGI-TPR-001 inventory and Part 2.1; CGI-ISO-001 A.5.8, A.5.10; CGI-POL-001 s4.5 | V4: VR-005; VR-006; VR-001; R-003; AR-001 | W4: AF-01; AF-04; AF-06; AF-07; AF-09 | X4: 1
A5: AIS-02 | B5: ChatCo AI features | C5: ChatCo (CGI-VEN-004) | D5: AI features inside team chat that read message content to answer questions and summarise channels | E5: Recorded as processing message content (VRA-2026-002 F-004, 15 Sep 2026). Action R4 (switch off by 01 Oct 2026) has no completion evidence, so treated as on (AI-A04) | F5: Bundled into a Tier 1 supplier's plan; AI terms never read at procurement | G5: IT Operations Manager | H5: 50 users; 3 shared channels with customers | I5: Message content, pasted credentials and screenshots, incident traffic, customers' posts in shared channels | J5: AI answers and channel summaries inside ChatCo (internal) | K5: Confidential | L5: Cypher staff; customer staff posting in shared channels | M5: Deployer | N5: Art. 3(4) | O5: Minimal (no AI Act duty beyond Art. 4 and Art. 5) | P5: Art. 6(2) + Annex III (no listed use); Art. 50(3)-(4) not triggered | Q5: Art. 50(1) and 50(2) for ChatCo's assistant | R5: Not Met: training not contractually prohibited; human review not excluded (F-004, VQ-68 and VQ-69) | S5: Not executed (F-001) | T5: None recorded for AI output | U5: CGI-TPR-001 VRA-2026-002 F-004 and action R4 | V5: VR-006; VR-001; R-003 | W5: AF-02; AF-04; AF-07 | X5: 2
A6: AIS-03 | B6: WriteCo writing assistant | C6: WriteCo (CGI-VEN-013) | D6: Browser extension that reads text typed into web fields and suggests or drafts rewrites | E6: In use on 12 seats. Assessed Pass with conditions (extension scope restricted); Tier 2 by trigger T2-f | F6: Individual licences on expense; brought under CGI-TPR-001 by T2-f | G6: Head of People and Operations | H6: 12 seats | I6: Any text typed into a web field: ChatCo, WikiCo, the CGI admin console, email | J6: Suggested and drafted text that staff send onwards | K6: Confidential | L6: Cypher staff; recipients of drafted text, including customers | M6: Deployer | N6: Art. 3(4) | O6: Minimal (no AI Act duty beyond Art. 4 and Art. 5) | P6: Art. 6(2) + Annex III (no listed use); Art. 25(1)(c) watch: an HR use could make Cypher a provider | Q6: Art. 50(2) marking of generated text (Art. 111(4) grace to 2 Dec 2026 if on the market before 2 Aug 2026) | R6: Not evidenced: individual licences, no executed terms | S6: None: individual licences on expense | T6: Author edits before sending (by design, not recorded) | U6: CGI-TPR-001 inventory, tiering Part 3 (T2-f), Gate A | V6: VR-006; VR-005; VR-001; R-003; AR-001 | W6: AF-03; AF-04; AF-05; AF-07 | X6: 3
A7: AIS-04 | B7: AI-A01 project assistant (scenario) | C7: ModelCo, a general-purpose model provider (scenario; not counted in CGI-TPR-001) | D7: Planned in-product assistant: answers a customer's questions about their own projects and drafts status summaries | E7: Scenario assumption AI-A01: design gate 31 Mar 2027, planned launch 01 Sep 2027. Not live; excluded from every earlier project's numbers | F7: Product roadmap (scenario) | G7: Chief Technology Officer | H7: About 200 customer organisations at launch | I7: Customer project content; users' prompts | J7: Generated answers and summaries shown to customer users | K7: Confidential (customer content) | L7: Customer users; their team members named in projects | M7: Provider (and downstream provider) | N7: Art. 3(3); Art. 3(68) | O7: Transparency (Art. 50) at launch; not high-risk while the intended purpose excludes judging workers | P7: Art. 50(1) and 50(2); Art. 6(2) + Annex III point 4(b) excluded by the intended-purpose statement | Q7: ModelCo: Chapter V GPAI model duties (since 2 Aug 2025) | R7: Design requirement: zero retention and no training, by contract | S7: Required before build: ModelCo DPA; customer sub-processor notice | T7: Design requirement: user reviews before sharing; feedback and stop control | U7: Declared here (Part 2.3); scenario only | V7: R-004; AR-002; VR-006 | W7: AF-13 | X7: Not ranked (not live)

Sheet 02_AI_Act_Tests
A1: Part 3 - EU AI Act applicability: eight tests per system, each with its article.
A3: AI system ID | B3: AI system | C3: 1. AI system? (Art. 3(1)) | D3: 2. Cypher's role (Art. 3, Art. 25) | E3: 3. Prohibited practice? (Art. 5) | F3: 4. Annex I product? (Art. 6(1)) | G3: 5. Annex III use? (Art. 6(2)) | H3: 6. Art. 6(3) needed? | I3: 7. Art. 50 duty on Cypher? | J3: 8. GPAI model duties on Cypher? (Chapter V) | K3: Tier for Cypher | L3: Applies today | M3: Applies later | N3: What would change the answer
A4: AIS-01 | B4: ScribeCo meeting assistant | C4: Yes: infers transcripts and summaries from audio | D4: Deployer. Not provider: no own name, no modification, no change of purpose | E4: No, subject to AI-A02. Emotion inference from voice at work would be Art. 5(1)(f); sentiment from transcript text alone is not emotion recognition (Art. 3(39) needs biometric data) | F4: No | G4: No: transcription is not in any of the eight Annex III areas | H4: No (not an Annex III use) | I4: No: Art. 50(3) and 50(4) not triggered. Art. 50(1) and 50(2), if they apply, are ScribeCo's | J4: No | K4: Minimal | L4: Art. 4 AI literacy measures; Art. 5 do-not-use. Outside the Act: GDPR Arts 13-14 notice, 28 contract, 35 DPIA, 44-46 transfer | M4: Nothing new under the Act while the use stays the same | N4: Using summaries to assess staff performance (Annex III 4(b), from 2 Dec 2027, and Cypher may become provider under Art. 25(1)(c)); enabling voice emotion analysis on internal calls (prohibited now)
A5: AIS-02 | B5: ChatCo AI features | C5: Yes | D5: Deployer | E5: No | F5: No | G5: No | H5: No | I5: No: Art. 50(1) and 50(2) are ChatCo's | J5: No | K5: Minimal | L5: Art. 4; Art. 5. Outside the Act: GDPR Art. 28 (no DPA), Art. 35 screening before re-enabling | M5: Nothing new under the Act | N5: Using chat analytics to score staff behaviour (Annex III 4(b))
A6: AIS-03 | B6: WriteCo writing assistant | C6: Yes | D6: Deployer | E6: No | F6: No | G6: No | H6: No | I6: No: Art. 50(4) applies only to AI text published to inform the public on matters of public interest, and a person edits every draft. Art. 50(2) is WriteCo's | J6: No | K6: Minimal | L6: Art. 4; Art. 5. Outside the Act: GDPR Art. 28 (no DPA) | M6: From 2 Dec 2026 WriteCo itself must mark generated text (Art. 111(4)); no new duty for Cypher | N6: HR using it to rank applicants or rate staff: Annex III 4(a)/(b) from 2 Dec 2027, and Art. 25(1)(c) would make Cypher the provider of a high-risk system
A7: AIS-04 | B7: AI-A01 project assistant (scenario) | C7: Yes | D7: Provider (Art. 3(3)) and downstream provider (Art. 3(68)); ModelCo is the GPAI model provider | E7: No, by design | F7: No | G7: Not while the intended-purpose statement excludes monitoring or evaluating workers. A 'who on my team is underperforming' feature would be Annex III 4(b) | H7: Not needed if 4(b) is designed out; if relied on, it must be documented before launch | I7: Yes, at launch: Art. 50(1) tell users they are dealing with AI; Art. 50(2) machine-readable marking of generated text | J7: No, unless Cypher modifies the model itself on a large scale (Commission GPAI guidelines) | K7: Transparency | L7: Nothing yet (not on the market). Art. 4 from the start of development | M7: At launch (planned 01 Sep 2027): Art. 50(1), 50(2), Art. 4 | N7: Adding staff-performance features (high-risk, Annex III 4(b)); fine-tuning ModelCo's model at scale (GPAI model provider)

Sheet 03_Timeline
A1: Part 3.3 - what applies today and what applies later (checked 17 Oct 2026).
A3: Date | B3: What starts to apply | C3: Article | D3: Applies to Cypher? | E3: How
A4: 02 Feb 2025 | B4: Prohibited practices (eight) | C4: Art. 5 | D4: Yes | E4: A do-not-use duty for every system. No current system does any of them (AI-A02, AI-A03).
A5: 02 Feb 2025 | B5: AI literacy (rewritten 27 Jul 2026: 'take measures to support') | C5: Art. 4 | D5: Yes | E5: As deployer of AIS-01 to AIS-03; as provider of AIS-04 from development. Supervised nationally since 02 Aug 2026.
A6: 02 Aug 2025 | B6: General-purpose AI model obligations; national penalty regimes | C6: Chapter V; Art. 99 | D6: No | E6: Cypher provides no general-purpose model. The duties sit with the model providers behind ScribeCo, ChatCo, WriteCo and ModelCo.
A7: 27 Jul 2026 | B7: Digital Omnibus on AI in force | C7: Reg. (EU) 2026/1744 | D7: Yes | E7: Article 4 rewritten; high-risk dates moved; small mid-cap category created.
A8: 02 Aug 2026 | B8: Transparency duties | C8: Art. 50 | D8: Not as deployer | E8: No Art. 50(3) or 50(4) use. As provider of AIS-04, at launch.
A9: 02 Dec 2026 | B9: Two new prohibitions (non-consensual intimate content; child sexual abuse material) | C9: Art. 5(1)(ba), (bb) | D9: Yes (do-not-use) | E9: No current system generates images or video.
A10: 02 Dec 2026 | B10: Marking deadline for generative systems on the market before 02 Aug 2026 | C10: Art. 111(4) | D10: No | E10: A provider duty. Affects ScribeCo, ChatCo and WriteCo, not Cypher.
A11: 02 Dec 2027 | B11: High-risk rules, Annex III route | C11: Art. 113, as amended | D11: No today | E11: Only if an Annex III use begins (AR-002). The census AIG-04 confirms none exists.
A12: 02 Aug 2028 | B12: High-risk rules, Annex I route | C12: Art. 113, as amended | D12: No | E12: Cypher makes no product covered by Annex I.

Sheet 04_Clauses
A1: Part 4.2 - ISO/IEC 42001 clauses 4-10. Score 0 absent, 1 partial or designed, 2 met with evidence (CGI-ISO-001 method).
A3: Clause | B3: Requirement (paraphrased) | C3: Stage 1 gate (Y/N) | D3: Score (0-2) | E3: Current state | F3: Gap | G3: Evidence needed | H3: 27001 evidence reusable for a joint system | I3: Owner (job title) | J3: Action | K3: Due
A4: 4.1 | B4: Understand the organisation's context for AI, including its role for each AI system and the intended purpose of the systems it uses or provides | C4: N | D4: 1 | E4: Roles and purposes drafted in this document (Part 2); AI vendors identified by CGI-TPR-001 T2-f. | F4: Not approved; no context statement for AI. | G4: Approved AI context and role statement. | H4: Partial: extend the ISO-01 context and issues statement | I4: Chief Executive Officer | J4: AIG-07; ISO-01 | K4: 31 Dec 2026
A5: 4.2 | B5: Interested parties and their AI-related requirements, including legal ones | C5: N | D5: 1 | E5: Customers on calls and in shared channels, staff and the GDPR authority are known from CGI-TPR-001 and CGI-POL-005. | F5: AI Act and GDPR AI duties are in no obligations register. | G5: Obligations register with the AI Act rows from Part 3. | H5: Yes: the ISO-01 interested-parties and obligations register (A.5.31) | I5: Chief Executive Officer | J5: AIG-11; ISO-01 | K5: 30 Jun 2027
A6: 4.3 | B6: Decide and document the scope of the AI management system | C6: Y | D6: 1 | E6: Drafted in Part 4.1 of this document. | F6: Not approved. | G6: CEO-approved AIMS scope. | H6: Partial: same format as the ISO-02 ISMS scope | I6: Chief Executive Officer | J6: AIG-07 | K6: 31 Dec 2026
A7: 4.4 | B7: Establish, run, maintain and improve the AI management system | C7: N | D7: 1 | E7: Pieces exist: CGI-POL-001 s4.5, tiering trigger T2-f, questionnaire domain 15. | F7: They do not run as one system; AI tools bypassed them. | G7: AIMS overview linking the processes. | H7: Yes: fold into the ISO-08 ISMS overview | I7: Chief Technology Officer | J7: AIG-11 | K7: 30 Jun 2027
A8: 5.1 | B8: Top management shows leadership and commitment to the AIMS | C8: N | D8: 1 | E8: The CEO approved CGI-POL-001 (including s4.5) and CGI-TPR-001 (including T2-f). | F8: No stated commitment or resources for AI governance. | G8: AI policy signed by the CEO; resources agreed. | H8: Partial: same sign-off route as ISO-03 | I8: Chief Executive Officer | J8: AIG-07 | K8: 31 Dec 2026
A9: 5.2 | B9: An AI policy that fits the organisation, sets a framework for AI objectives and commits to meeting requirements and improving | C9: N | D9: 1 | E9: CGI-POL-001 s4.5: four clauses on staff use of AI tools. | F9: A clause is not a capability: s4.5 covers staff tool use only, not objectives, impact assessment, oversight or prohibited uses. | G9: AI policy v1.0, communicated. | H9: Partial: reuse the ISO-03 policy template | I9: Chief Executive Officer | J9: AIG-07 | K9: 31 Dec 2026
A10: 5.3 | B10: Roles, responsibilities and authorities for the AIMS assigned and communicated | C10: N | D10: 1 | E10: The CTO keeps the approved AI tools list and assesses requests (CGI-POL-001 s4.5.1, s4.5.4). | F10: No AI governance lead, no impact-assessment or oversight roles. | G10: Written AI roles in the ISO-04 RACI. | H10: Yes: extend the ISO-04 RACI | I10: Chief Executive Officer | J10: AIG-07; ISO-04 | K10: 31 Dec 2026
A11: 6.1.1 | B11: Determine the AIMS's own risks and opportunities and plan actions | C11: N | D11: 0 | E11: None. | F11: Not considered. | G11: AIMS risks and opportunities record. | H11: Yes: same record as ISO-08 (6.1.1) | I11: Chief Technology Officer | J11: AIG-11 | K11: 30 Jun 2027
A12: 6.1.2 | B12: An AI risk assessment process with criteria that cover harm to people, not only to the organisation | C12: Y | D12: 1 | E12: CGI-RSK-001 applies NIST SP 800-30 and has scored AI risks (VR-005, VR-006, and AR-001/AR-002 here). | F12: No acceptance criteria (GAP-002) and no harm-to-people criteria. | G12: AI risk criteria added to the ISO-05 acceptance criteria. | H12: Partial: extend ISO-05 | I12: Chief Executive Officer | J12: AIG-11; ISO-05 | K12: 30 Jun 2027
A13: 6.1.3 | B13: AI risk treatment: choose controls, compare with Annex A, produce a Statement of Applicability, get owners' approval | C13: Y | D13: 1 | E13: SoA drafted in Part 4.2 (38 controls). | F13: Not approved; treatment plans TP-11 and TP-12 proposed only. | G13: Approved AI SoA and treatment plan. | H13: Partial: one combined SoA approval at ISO-06 | I13: Chief Executive Officer | J13: AIG-11; ISO-06 | K13: 30 Jun 2027
A14: 6.1.4 | B14: An AI system impact assessment process covering effects on individuals, groups and society | C14: Y | D14: 1 | E14: Process and two assessments drafted in Part 5. | F14: Not approved; no trigger rule in the onboarding workflow. | G14: Approved process; trigger in CGI-TPR-001 for every AI tool. | H14: No: AI-specific | I14: Chief Technology Officer | J14: AIG-05; AIG-07 | K14: 31 Dec 2026
A15: 6.2 | B15: Measurable AI objectives and plans to achieve them | C15: N | D15: 0 | E15: None. | F15: No AI objectives. | G15: Objectives with owners and targets. | H15: Partial: add to the ISO-07 objectives plan | I15: Chief Technology Officer | J15: AIG-11; ISO-07 | K15: 30 Jun 2027
... A33: 10.2 | B33: React to nonconformities and take corrective action | C33: N | D33: 0 | E33: None. ScribeCo's breach of CGI-POL-001 s4.5 was never raised as a nonconformity. | F33: No corrective-action record. | G33: Corrective-action log entry for ScribeCo. | H33: Yes: ISO-08 / ISO-15 log | I33: Chief Technology Officer | J33: AIG-01 | K33: 24 Oct 2026
A35: Total | D35: =SUM(D4:D33) -> 18
A36: Maximum | D36: =2*COUNTA(A4:A33) -> 60
A37: Clause score | D37: =D35/D36 -> 0.3
A38: Gates failing | D38: =COUNTIFS(C4:C33,"Y",D4:D33,"<2") -> 9

Sheet 05_Annex_A
A1: Part 4.3 - ISO/IEC 42001 Annex A, all 38 controls. Status is a formula over maturity (0 Not started, 1-2 Partial, 3-4 Implemented).
A3: Control | B3: Title | C3: Group | D3: What it asks (paraphrased) | E3: Applicable (Y/N) | F3: Justification | G3: Maturity (0-4) | H3: Status (derived) | I3: Evidence held / required | J3: Owner (job title) | K3: Related risk ID | L3: Related AI Act article | M3: Related ISO/IEC 27001 control | N3: Related finding | O3: Roadmap | P3: Target date
A4: A.2.2 | B4: AI policy | C4: A.2 Policies related to AI | D4: A documented policy for developing or using AI systems | E4: Y | F4: Cypher uses three AI systems (AIS-01 to AIS-03). | G4: 1 | H4: =IF(E4="N","-",IF(G4=0,"Not started",IF(G4<=2,"Partial","Implemented"))) -> Partial | I4: Held: CGI-POL-001 s4.5 (four clauses on staff use; a fragment). Required: AI policy v1.0. | J4: Chief Executive Officer | K4: VR-005; VR-006; AR-002 | L4: Art. 4; Art. 5 | M4: A.5.1 | N4: AF-08 | O4: AIG-07 | P4: 31 Dec 2026
A5: A.2.3 | B5: Alignment with other organizational policies | C5: A.2 Policies related to AI | D5: Know where other policies touch AI and keep them consistent | E5: Y | F5: AI use touches acceptable use, classification and supplier policies. | G5: 2 | H5: =IF(E5="N","-",IF(G5=0,"Not started",IF(G5<=2,"Partial","Implemented"))) -> Partial | I5: Held: s4.5 sits inside CGI-POL-001 and uses CGI-POL-004 classes. Required: evidence of a consistency review. | J5: Chief Technology Officer | K5: VR-006 | L5: - | M5: A.5.1 | N5: AF-08 | O5: AIG-07 | P5: 31 Dec 2026
A6: A.2.4 | B6: Review of the AI policy | C6: A.2 Policies related to AI | D6: Review the AI policy at planned intervals and on change | E6: Y | F6: Needed once an AI policy exists. | G6: 1 | H6: =IF(E6="N","-",IF(G6=0,"Not started",IF(G6<=2,"Partial","Implemented"))) -> Partial | I6: Held: CGI-POL-001 annual review date. Required: review criteria covering new tools and legal change (the Omnibus rewrote Art. 4). | J6: Chief Technology Officer | K6: VR-005 | L6: Art. 4 | M6: A.5.1 | N6: AF-08 | O6: AIG-07 | P6: 31 Dec 2026
A7: A.3.2 | B7: AI roles and responsibilities | C7: A.3 Internal organization | D7: Define and allocate AI roles | E7: Y | F7: Owners exist per tool; nobody owns AI governance. | G7: 1 | H7: =IF(E7="N","-",IF(G7=0,"Not started",IF(G7<=2,"Partial","Implemented"))) -> Partial | I7: Held: CTO list-keeper role (s4.5.1). Required: AI lead, impact-assessment owner, reviewers. | J7: Chief Executive Officer | K7: VR-005; AR-001 | L7: Art. 4 | M7: A.5.2 | N7: AF-08 | O7: AIG-07 | P7: 31 Dec 2026
A8: A.3.3 | B8: Reporting of concerns | C8: A.3 Internal organization | D8: A way for people to report concerns about an AI system | E8: Y | F8: Staff and customers see AI output first. | G8: 1 | H8: =IF(E8="N","-",IF(G8=0,"Not started",IF(G8<=2,"Partial","Implemented"))) -> Partial | I8: Held: CGI-POL-005 incident reporting (not AI-specific). Required: AI concern category and route. | J8: Chief Technology Officer | K8: AR-001 | L8: - | M8: A.6.8 | N8: AF-10 | O8: AIG-10 | P8: 31 Jan 2027
A9: A.4.2 | B9: Resource documentation | C9: A.4 Resources for AI systems | D9: Document the resources each AI system relies on | E9: Y | F9: A deployer must know what each system uses and touches. | G9: 1 | H9: =IF(E9="N","-",IF(G9=0,"Not started",IF(G9<=2,"Partial","Implemented"))) -> Partial | I9: Held: AI register drafted here. Required: register approved and kept current. | J9: Chief Technology Officer | K9: VR-005 | L9: Art. 4 | M9: A.5.9 | N9: AF-03 | O9: AIG-03 | P9: 31 Oct 2026
A10: A.4.3 | B10: Data resources | C10: A.4 Resources for AI systems | D10: Document the data each AI system uses | E10: Y | F10: Applicable to the data Cypher feeds in. | G10: 1 | H10: =IF(E10="N","-",IF(G10=0,"Not started",IF(G10<=2,"Partial","Implemented"))) -> Partial | I10: Held: data-in column of the AI register (from the CGI-TPR-001 inventory). Required: owner confirmation. | J10: Chief Technology Officer | K10: VR-006 | L10: - | M10: A.5.12 | N10: AF-03 | O10: AIG-03 | P10: 31 Oct 2026
A11: A.4.4 | B11: Tooling resources | C11: A.4 Resources for AI systems | D11: Document tools used to build AI systems | E11: N | F11: Not applicable while Cypher develops no AI system (AI register, Part 2). Becomes applicable at the AI-A01 design gate (AIG-13). | H11: =IF(E11="N","-",IF(G11=0,"Not started",IF(G11<=2,"Partial","Implemented"))) -> - | I11: - | J11: Chief Technology Officer | K11: - | L11: - | M11: - | N11: AF-13 | O11: AIG-13 | P11: 31 Mar 2027
A12: A.4.5 | B12: System and computing resources | C12: A.4 Resources for AI systems | D12: Document computing resources used by AI systems | E12: N | F12: Not applicable while Cypher develops no AI system (AI register, Part 2). Becomes applicable at the AI-A01 design gate (AIG-13). For supplier AI the computing is the supplier's. | H12: =IF(E12="N","-",IF(G12=0,"Not started",IF(G12<=2,"Partial","Implemented"))) -> - | I12: - | J12: Chief Technology Officer | K12: - | L12: - | M12: - | N12: AF-13 | O12: AIG-13 | P12: 31 Mar 2027
A13: A.4.6 | B13: Human resources | C13: A.4 Resources for AI systems | D13: Document the people and competences AI systems need | E13: Y | F13: Oversight needs competent reviewers. | G13: 0 | H13: =IF(E13="N","-",IF(G13=0,"Not started",IF(G13<=2,"Partial","Implemented"))) -> Not started | I13: Held: none. Required: AI roles in the competence matrix. | J13: Head of People and Operations | K13: AR-001 | L13: Art. 4 | M13: A.6.3 | N13: AF-05 | O13: AIG-08 | P13: 31 Mar 2027
A14: A.5.2 | B14: AI system impact assessment process | C14: A.5 Assessing impacts of AI systems | D14: A process to assess consequences for people and society | E14: Y | F14: Two systems process people's conversations. | G14: 1 | H14: =IF(E14="N","-",IF(G14=0,"Not started",IF(G14<=2,"Partial","Implemented"))) -> Partial | I14: Held: process drafted in Part 5. Required: approval; trigger in CGI-TPR-001. | J14: Chief Technology Officer | K14: VR-006; AR-001 | L14: - | M14: A.5.34 | N14: AF-07 | O14: AIG-05 | P14: 30 Nov 2026
A15: A.5.3 | B15: Documentation of AI system impact assessments | C15: A.5 Assessing impacts of AI systems | D15: Record and keep impact assessment results | E15: Y | F15: Same. | G15: 1 | H15: =IF(E15="N","-",IF(G15=0,"Not started",IF(G15<=2,"Partial","Implemented"))) -> Partial | I15: Held: AIIA-01 and AIIA-02 (this document). Required: owner approval; retention rule. | J15: Chief Technology Officer | K15: VR-006 | L15: - | M15: A.5.34 | N15: AF-07 | O15: AIG-05 | P15: 30 Nov 2026
A16: A.5.4 | B16: Assessing impacts on individuals or groups | C16: A.5 Assessing impacts of AI systems | D16: Assess effects on individuals and groups | E16: Y | F16: Customers and staff are recorded on calls. | G16: 1 | H16: =IF(E16="N","-",IF(G16=0,"Not started",IF(G16<=2,"Partial","Implemented"))) -> Partial | I16: Held: harm tables in AIIA-01 and AIIA-02. Required: approval. | J16: Chief Technology Officer | K16: AR-001; AR-002 | L16: Art. 5(1)(f) | M16: A.5.34 | N16: AF-07 | O16: AIG-05 | P16: 30 Nov 2026
A17: A.5.5 | B17: Assessing societal impacts of AI systems | C17: A.5 Assessing impacts of AI systems | D17: Assess wider effects on society | E17: Y | F17: Required by the process even when the answer is small. | G17: 1 | H17: =IF(E17="N","-",IF(G17=0,"Not started",IF(G17<=2,"Partial","Implemented"))) -> Partial | I17: Held: societal section in AIIA-01 and AIIA-02 (negligible at this scale). Required: approval. | J17: Chief Technology Officer | K17: - | L17: - | M17: - | N17: AF-07 | O17: AIG-05 | P17: 30 Nov 2026
A18: A.6.1.2 | B18: Objectives for responsible development of AI systems | C18: A.6 AI system life cycle | D18: Objectives that guide AI development | E18: N | F18: Not applicable while Cypher develops no AI system (AI register, Part 2). Becomes applicable at the AI-A01 design gate (AIG-13). | H18: =IF(E18="N","-",IF(G18=0,"Not started",IF(G18<=2,"Partial","Implemented"))) -> - | I18: - | J18: Chief Technology Officer | K18: - | L18: - | M18: - | N18: AF-13 | O18: AIG-13 | P18: 31 Mar 2027
A19: A.6.1.3 | B19: Processes for responsible design and development | C19: A.6 AI system life cycle | D19: Processes for responsible design and development | E19: N | F19: Not applicable while Cypher develops no AI system (AI register, Part 2). Becomes applicable at the AI-A01 design gate (AIG-13). | H19: =IF(E19="N","-",IF(G19=0,"Not started",IF(G19<=2,"Partial","Implemented"))) -> - | I19: - | J19: Chief Technology Officer | K19: - | L19: - | M19: - | N19: AF-13 | O19: AIG-13 | P19: 31 Mar 2027
A20: A.6.2.2 | B20: AI system requirements and specification | C20: A.6 AI system life cycle | D20: Specify requirements for new AI systems | E20: N | F20: Not applicable while Cypher develops no AI system (AI register, Part 2). Becomes applicable at the AI-A01 design gate (AIG-13). Buying supplier AI is governed by A.10.3. | H20: =IF(E20="N","-",IF(G20=0,"Not started",IF(G20<=2,"Partial","Implemented"))) -> - | I20: - | J20: Chief Technology Officer | K20: - | L20: - | M20: - | N20: AF-13 | O20: AIG-13 | P20: 31 Mar 2027
A21: A.6.2.3 | B21: Documentation of AI system design and development | C21: A.6 AI system life cycle | D21: Document design and development | E21: N | F21: Not applicable while Cypher develops no AI system (AI register, Part 2). Becomes applicable at the AI-A01 design gate (AIG-13). | H21: =IF(E21="N","-",IF(G21=0,"Not started",IF(G21<=2,"Partial","Implemented"))) -> - | I21: - | J21: Chief Technology Officer | K21: - | L21: - | M21: - | N21: AF-13 | O21: AIG-13 | P21: 31 Mar 2027
A22: A.6.2.4 | B22: AI system verification and validation | C22: A.6 AI system life cycle | D22: Check the system works as intended before use | E22: Y | F22: A deployer should test a tool on its own calls before trusting it. Nobody has checked ScribeCo's accuracy. | G22: 0 | H22: =IF(E22="N","-",IF(G22=0,"Not started",IF(G22<=2,"Partial","Implemented"))) -> Not started | I22: Held: none. Required: an acceptance test (sample of summaries checked against recordings). | J22: Head of Customer Success | K22: AR-001 | L22: - | M22: A.8.29 | N22: AF-06 | O22: AIG-09 | P22: 31 Jan 2027
A23: A.6.2.5 | B23: AI system deployment | C23: A.6 AI system life cycle | D23: Plan deployment and confirm requirements are met first | E23: Y | F23: Every tool Cypher puts into use is a deployment. | G23: 0 | H23: =IF(E23="N","-",IF(G23=0,"Not started",IF(G23<=2,"Partial","Implemented"))) -> Not started | I23: Held: none; two tools arrived on expenses. Required: deployment checklist in the onboarding workflow. | J23: Chief Technology Officer | K23: VR-005 | L23: - | M23: A.5.8 | N23: AF-03 | O23: AIG-03 | P23: 31 Oct 2026
A24: A.6.2.6 | B24: AI system operation and monitoring | C24: A.6 AI system life cycle | D24: Operate and monitor the system, including errors and misuse | E24: Y | F24: Output errors are the AR-001 risk. | G24: 0 | H24: =IF(E24="N","-",IF(G24=0,"Not started",IF(G24<=2,"Partial","Implemented"))) -> Not started | I24: Held: none. Required: review log sample; error reporting. | J24: Head of Customer Success | K24: AR-001 | L24: - | M24: A.8.16 | N24: AF-06 | O24: AIG-09 | P24: 31 Jan 2027
A25: A.6.2.7 | B25: AI system technical documentation | C25: A.6 AI system life cycle | D25: Technical documentation for users and others | E25: N | F25: Not applicable while Cypher develops no AI system (AI register, Part 2). Becomes applicable at the AI-A01 design gate (AIG-13). Supplier documentation is collected under A.8.2 and A.10.3. | H25: =IF(E25="N","-",IF(G25=0,"Not started",IF(G25<=2,"Partial","Implemented"))) -> - | I25: - | J25: Chief Technology Officer | K25: - | L25: Art. 50 (AIS-04) | M25: - | N25: AF-13 | O25: AIG-13 | P25: 31 Mar 2027
A26: A.6.2.8 | B26: AI system recording of event logs | C26: A.6 AI system life cycle | D26: Keep event logs for the system | E26: Y | F26: Cypher should know who used which tool on which meeting. | G26: 0 | H26: =IF(E26="N","-",IF(G26=0,"Not started",IF(G26<=2,"Partial","Implemented"))) -> Not started | I26: Held: none. Required: admin usage export kept 6 months. | J26: IT Operations Manager | K26: VR-005 | L26: - | M26: A.8.15 | N26: AF-03 | O26: AIG-03 | P26: 31 Oct 2026
A27: A.7.2 | B27: Data for development and enhancement of AI systems | C27: A.7 Data for AI systems | D27: Manage data used to build or improve AI | E27: N | F27: Not applicable while Cypher develops no AI system (AI register, Part 2). Becomes applicable at the AI-A01 design gate (AIG-13). A supplier training on Cypher's data is a supplier control (A.10.3, VR-006). | H27: =IF(E27="N","-",IF(G27=0,"Not started",IF(G27<=2,"Partial","Implemented"))) -> - | I27: - | J27: Chief Technology Officer | K27: - | L27: - | M27: - | N27: AF-13 | O27: AIG-13 | P27: 31 Mar 2027
A28: A.7.3 | B28: Acquisition of data | C28: A.7 Data for AI systems | D28: Govern how training data is acquired | E28: N | F28: Not applicable while Cypher develops no AI system (AI register, Part 2). Becomes applicable at the AI-A01 design gate (AIG-13). | H28: =IF(E28="N","-",IF(G28=0,"Not started",IF(G28<=2,"Partial","Implemented"))) -> - | I28: - | J28: Chief Technology Officer | K28: - | L28: - | M28: - | N28: AF-13 | O28: AIG-13 | P28: 31 Mar 2027
A29: A.7.4 | B29: Quality of data for AI systems | C29: A.7 Data for AI systems | D29: Define and meet data quality requirements | E29: N | F29: Not applicable while Cypher develops no AI system (AI register, Part 2). Becomes applicable at the AI-A01 design gate (AIG-13). | H29: =IF(E29="N","-",IF(G29=0,"Not started",IF(G29<=2,"Partial","Implemented"))) -> - | I29: - | J29: Chief Technology Officer | K29: - | L29: - | M29: - | N29: AF-13 | O29: AIG-13 | P29: 31 Mar 2027
A30: A.7.5 | B30: Data provenance | C30: A.7 Data for AI systems | D30: Record where data came from | E30: N | F30: Not applicable while Cypher develops no AI system (AI register, Part 2). Becomes applicable at the AI-A01 design gate (AIG-13). | H30: =IF(E30="N","-",IF(G30=0,"Not started",IF(G30<=2,"Partial","Implemented"))) -> - | I30: - | J30: Chief Technology Officer | K30: - | L30: - | M30: - | N30: AF-13 | O30: AIG-13 | P30: 31 Mar 2027
A31: A.7.6 | B31: Data preparation | C31: A.7 Data for AI systems | D31: Define how data is prepared | E31: N | F31: Not applicable while Cypher develops no AI system (AI register, Part 2). Becomes applicable at the AI-A01 design gate (AIG-13). | H31: =IF(E31="N","-",IF(G31=0,"Not started",IF(G31<=2,"Partial","Implemented"))) -> - | I31: - | J31: Chief Technology Officer | K31: - | L31: - | M31: - | N31: AF-13 | O31: AIG-13 | P31: 31 Mar 2027
A32: A.8.2 | B32: System documentation and information for users | C32: A.8 Information for interested parties | D32: Give users the information they need to use the system properly | E32: Y | F32: Staff need to know what each tool may and may not be used for. | G32: 0 | H32: =IF(E32="N","-",IF(G32=0,"Not started",IF(G32<=2,"Partial","Implemented"))) -> Not started | I32: Held: none; no AI-use instruction (OFI-04). Required: one-page use guide per approved tool. | J32: Chief Technology Officer | K32: AR-001; VR-006 | L32: Art. 4 | M32: A.5.10 | N32: AF-05 | O32: AIG-08 | P32: 31 Dec 2026
A33: A.8.3 | B33: External reporting | C33: A.8 Information for interested parties | D33: Let outside parties report adverse impacts | E33: Y | F33: Customers are the first to see a wrong summary. | G33: 0 | H33: =IF(E33="N","-",IF(G33=0,"Not started",IF(G33<=2,"Partial","Implemented"))) -> Not started | I33: Held: none. Required: customer route for AI concerns. | J33: Head of Customer Success | K33: AR-001 | L33: - | M33: A.6.8 | N33: AF-10 | O33: AIG-10 | P33: 31 Jan 2027
A34: A.8.4 | B34: Communication of incidents | C34: A.8 Information for interested parties | D34: Tell affected parties about AI incidents | E34: Y | F34: AI incidents can be data incidents. | G34: 1 | H34: =IF(E34="N","-",IF(G34=0,"Not started",IF(G34<=2,"Partial","Implemented"))) -> Partial | I34: Held: CGI-POL-005 customer and regulator communications (RS.CO = 2). Required: AI incident type. | J34: Chief Technology Officer | K34: VR-006 | L34: - | M34: A.5.24 | N34: AF-10 | O34: AIG-10 | P34: 31 Jan 2027
A35: A.8.5 | B35: Information for interested parties | C35: A.8 Information for interested parties | D35: Decide what to tell interested parties about AI and tell them | E35: Y | F35: Customers on calls are not told they are transcribed. | G35: 0 | H35: =IF(E35="N","-",IF(G35=0,"Not started",IF(G35<=2,"Partial","Implemented"))) -> Not started | I35: Held: none. Required: call notice; AI sub-processors on the customer list. | J35: Head of Customer Success | K35: VR-006 | L35: - | M35: A.5.34 | N35: AF-09 | O35: AIG-06 | P35: 30 Nov 2026
A36: A.9.2 | B36: Processes for responsible use of AI systems | C36: A.9 Use of AI systems | D36: Define how AI systems may be used responsibly | E36: Y | F36: Core control for a deployer. | G36: 2 | H36: =IF(E36="N","-",IF(G36=0,"Not started",IF(G36<=2,"Partial","Implemented"))) -> Partial | I36: Held: CGI-POL-001 s4.5.1 to s4.5.4 (approved). Contradicted by ScribeCo; cannot reach 3 until operating evidence exists. Required: approved list; review records. | J36: Chief Technology Officer | K36: VR-005; VR-006; AR-001 | L36: Art. 4 | M36: A.5.10 | N36: AF-03 | O36: AIG-03 | P36: 31 Oct 2026
A37: A.9.3 | B37: Objectives for responsible use of AI systems | C37: A.9 Use of AI systems | D37: Set objectives for responsible use | E37: Y | F37: Needed to measure the AIMS. | G37: 0 | H37: =IF(E37="N","-",IF(G37=0,"Not started",IF(G37<=2,"Partial","Implemented"))) -> Not started | I37: Held: none. Required: AI objectives (ISO-07). | J37: Chief Technology Officer | K37: - | L37: - | M37: - | N37: AF-08 | O37: AIG-11 | P37: 30 Jun 2027
A38: A.9.4 | B38: Intended use of the AI system | C38: A.9 Use of AI systems | D38: Use the system as intended and per its documentation | E38: Y | F38: Stops drift into prohibited or high-risk uses. | G38: 1 | H38: =IF(E38="N","-",IF(G38=0,"Not started",IF(G38<=2,"Partial","Implemented"))) -> Partial | I38: Held: WriteCo extension scope restricted (CGI-TPR-001 condition). Required: intended-use and banned-use statement per tool. | J38: Chief Technology Officer | K38: AR-002 | L38: Art. 5; Art. 6(2); Art. 25(1)(c) | M38: A.5.10 | N38: AF-11 | O38: AIG-07 | P38: 31 Dec 2026
A39: A.10.2 | B39: Allocation of responsibilities | C39: A.10 Third-party and customer relationships | D39: Split AI responsibilities between the organisation, its suppliers and its customers | E39: Y | F39: All three systems in use are supplier AI. | G39: 2 | H39: =IF(E39="N","-",IF(G39=0,"Not started",IF(G39<=2,"Partial","Implemented"))) -> Partial | I39: Held: CGI-TPR-001 clause checklist incl. no-training clause (approved). Required: executed clauses for AI suppliers. | J39: Chief Technology Officer | K39: VR-006; VR-001 | L39: - | M39: A.5.20 | N39: AF-01; AF-02 | O39: AIG-01; AIG-02 | P39: 24 Oct 2026
A40: A.10.3 | B40: Suppliers | C40: A.10 Third-party and customer relationships | D40: Make sure supplier AI fits the organisation's approach to responsible AI | E40: Y | F40: All three systems in use are supplier AI. | G40: 2 | H40: =IF(E40="N","-",IF(G40=0,"Not started",IF(G40<=2,"Partial","Implemented"))) -> Partial | I40: Held: T2-f and questionnaire domain 15, operated once (WriteCo). Not 3: no review cycle has run (same reason GV.SC = 2). Required: ScribeCo decision; ChatCo DPA. | J40: Chief Technology Officer | K40: VR-005; VR-006 | L40: - | M40: A.5.19; A.5.21 | N40: AF-01; AF-02; AF-04 | O40: AIG-01; AIG-04 | P40: 30 Nov 2026
A41: A.10.4 | B41: Customers | C41: A.10 Third-party and customer relationships | D41: Consider customers' needs and expectations when AI touches their data | E41: Y | F41: Cypher is a processor for ~200 customers. | G41: 0 | H41: =IF(E41="N","-",IF(G41=0,"Not started",IF(G41<=2,"Partial","Implemented"))) -> Not started | I41: Held: none for AI. Required: AI sub-processors in the customer list and the SOC-02 system description. | J41: Chief Technology Officer | K41: VR-001 | L41: - | M41: A.5.34 | N41: AF-12 | O41: AIG-12 | P41: 30 Jun 2027
...

Sheet 06_Readiness
A1: Part 4.4 - readiness score and go / no-go. Every number is a formula over 04_Clauses and 05_Annex_A.
A3: Component | B3: Calculation | C3: Result | D3: Weight
A4: Clauses 4-10 | B4: Sum of 0-2 scores / (2 x requirements) | C4: =04_Clauses!$D$37 -> 0.3 | D4: 0.6
A5: Annex A | B5: (Implemented + 0.5 x Partial) / applicable | C5: =05_Annex_A!$H$50 -> 0.30769231 | D5: 0.4
A6: Weighted readiness | B6: 0.6 x clauses + 0.4 x Annex A | C6: =C4*D4+C5*D5 -> 0.30307692
A7: Gate requirements failing (of 9) | B7: Gates: 4.3, 6.1.2, 6.1.3, 6.1.4, 9.2.1, 9.2.2, 9.3.1, 9.3.2, 9.3.3 | C7: =04_Clauses!$D$38 -> 9
A8: Band | B8: >= 85% and no gate failure = Ready for Stage 1; 60-84% = within 90 days; < 60% = Not ready | C8: =IF(AND(C6>=0.85,C7=0),"Ready for Stage 1",IF(C6>=0.6,"Ready within 90 days","Not ready")) -> Not ready
A9: Go / no-go | B9: Any failed gate = NO-GO | C9: =IF(C7>0,"NO-GO","GO") -> NO-GO
A10: Sensitivity: AI-A01 in scope | B10: Excluded controls join at maturity 0 | C10: =0.6*C4+0.4*((05_Annex_A!$H$48+0.5*05_Annex_A!$H$47)/05_Annex_A!$H$43) -> 0.26421053

Sheet 07_Impact_Assessments
A1: Part 5 - AIIA-01 (ScribeCo) and AIIA-02 (ChatCo AI features). Triage below the table.
A3: Assessment | B3: Section | C3: Field | D3: Content
A4: AIIA-01 | B4: Identity | C4: System | D4: AIS-01 ScribeCo meeting assistant (CGI-VEN-012)
A5: AIIA-01 | B5: Identity | C5: Assessor / approver | D5: O.S / Head of Customer Success (owner), then Chief Executive Officer
A6: AIIA-01 | B6: Identity | C6: Date and trigger | D6: 17 Oct 2026. Trigger: shadow AI found 15 Sep 2026; no contract; decision overdue since 15 Oct 2026
A7: AIIA-01 | B7: Use | C7: Intended use | D7: Notes and summaries of internal and customer calls for Customer Success
A8: AIIA-01 | B8: Use | C8: Uses that must never happen | D8: Assessing staff performance from calls (Annex III 4(b)); inferring emotions from voice at work (Art. 5(1)(f))
A9: AIIA-01 | B9: Data | C9: Data in | D9: Live audio of about 40 meetings a month: voices, names, commercial terms, security discussion, any personal data spoken
A10: AIIA-01 | B10: Data | C10: Data out | D10: Transcripts, summaries and action items, stored by ScribeCo in the United States and shared by link
A11: AIIA-01 | B11: Data | C11: Model-training terms | D11: Unknown. No contract and no terms review, so VQ-68 and VQ-69 cannot be answered. Treat as 'may train, may review'
A12: AIIA-01 | B12: People | C12: Affected people | D12: Customer participants (individuals and their companies); Cypher staff (employees: power imbalance); third parties named on calls
A13: AIIA-01 | B13: Oversight | C13: Human oversight today | D13: None recorded. CGI-POL-001 s4.5.3 requires a competent person to review AI output before it reaches a customer
A14: AIIA-01 | B14: Oversight | C14: Oversight required | D14: Human-in-the-loop: the call owner checks every summary before it leaves Cypher; monthly sample of 10 checked against recordings
... A37: AIIA-02 | B37: Decision | C37: Recommendation | D37: Confirm the features are off today (screenshot). Re-enable only after a DPA with no-training and no-human-review clauses, a DPIA, retention limits (F-005) and AI switched off in shared channels

Sheet 08_Harm_Scores
A1: Part 5 - harms scored on the CGI-RSK-001 1-5 scales. Score = L x I.
A3: Assessment | B3: Harm ID | C3: Harm | D3: Who is affected | E3: Current L | F3: Current I | G3: Current score | H3: Measures | I3: Measure type | J3: After L | K3: After I | L3: After score
A4: AIIA-01 | B4: H1 | C4: Call content retained, reviewed or used for training by a supplier under no contract | D4: Customer participants; Cypher | E4: 4 | F4: 4 | G4: =E4*F4 -> 16 | H4: DPA with no-training and no-human-review clauses and a transfer mechanism (brakes); 30-day retention and deletion on exit (seatbelt) | I4: Brakes and seatbelt (two measures) | J4: 2 | K4: 3 | L4: =J4*K4 -> 6
A5: AIIA-01 | B5: H2 | C5: A wrong summary is acted on or sent to a customer (misstated commitments) | D5: Customers | E5: 3 | F5: 3 | G5: =E5*F5 -> 9 | H5: Call owner reviews every summary before it leaves Cypher (brakes); monthly accuracy sample of sent summaries (seatbelt: finds what slipped through) | I5: Brakes, checked by a seatbelt | J5: 2 | K5: 3 | L5: =J5*K5 -> 6
A6: AIIA-01 | B6: H3 | C6: People are recorded without being told | D6: Customer participants; staff; third parties | E6: 4 | F6: 2 | G6: =E6*F6 -> 8 | H6: Spoken and written notice at the start of every recorded call; bot shown by name | I6: Brakes | J6: 1 | K6: 2 | L6: =J6*K6 -> 2
A7: AIIA-01 | B7: H4 | C7: Use drifts into judging staff, or emotion inference from voice | D7: Staff | E7: 2 | F7: 4 | G7: =E7*F7 -> 8 | H7: Banned-use statement in the AI policy; feature check in AIG-04 | I7: Brakes | J7: 1 | K7: 4 | L7: =J7*K7 -> 4
A8: AIIA-02 | B8: H1 | C8: Message content (credentials, customer posts) used for training or human review | D8: Staff; customers in shared channels | E8: 4 | F8: 4 | G8: =E8*F8 -> 16 | H8: Features off until a DPA with no-training and no-human-review clauses | I8: Brakes | J8: 1 | K8: 4 | L8: =J8*K8 -> 4
A9: AIIA-02 | B9: H2 | C9: Customers in shared channels unaware their posts are processed by AI | D9: Customer staff | E9: 3 | F9: 2 | G9: =E9*F9 -> 6 | H9: AI off in shared channels; notice in channel description | I9: Brakes | J9: 1 | K9: 2 | L9: =J9*K9 -> 2
A10: AIIA-02 | B10: H3 | C10: A wrong incident-channel summary misleads the response | D10: Customers (indirectly) | E10: 2 | F10: 3 | G10: =E10*F10 -> 6 | H10: Rule: AI summaries are never the incident record | I10: Brakes | J10: 1 | K10: 3 | L10: =J10*K10 -> 3
A11: AIIA-02 | B11: H4 | C11: AI answers make pasted credentials and customer detail easier to find | D11: Staff; customers | E11: 3 | F11: 3 | G11: =E11*F11 -> 9 | H11: Retention limit (F-005); credential-pasting rule; secret rotation if found | I11: Brakes | J11: 2 | K11: 3 | L11: =J11*K11 -> 6
A13: Harms where 'after' exceeds 'now' | L13: =SUMPRODUCT(--(L4:L11>G4:G11)) -> 0

Sheet 09_DPIA_Screening
A1: Part 5.4 - GDPR Art. 35 screening against the nine EDPB criteria. Two or more usually means a DPIA is required.
A3: EDPB criterion | B3: AIS-01 ScribeCo | C3: AIS-02 ChatCo AI features | D3: AIS-03 WriteCo
A4: 1. Evaluation or scoring | B4: No | C4: No | D4: No
A5: 2. Automated decision with legal or similar effect | B5: No | C5: No | D5: No
A6: 3. Systematic monitoring | B6: Yes: every recorded call | C6: No | D6: No
A7: 4. Sensitive or highly personal data | B7: Yes: private communications | C7: Yes: private communications | D7: Yes: anything typed
A8: 5. Large scale | B8: No | C8: No | D8: No
A9: 6. Matching or combining datasets | B9: No | C9: No | D9: No
A10: 7. Vulnerable data subjects (employees) | B10: Yes | C10: Yes | D10: Yes
A11: 8. Innovative use or new technology | B11: Yes | C11: Yes | D11: Yes
A12: 9. Prevents exercising a right or using a service | B12: No | C12: No | D12: No
A13: Criteria met | B13: =COUNTIF(B4:B12,"Yes*") -> 4 | C13: =COUNTIF(C4:C12,"Yes*") -> 3 | D13: =COUNTIF(D4:D12,"Yes*") -> 3
A14: Result | B14: =IF(B13>=2,"DPIA required","No DPIA") -> DPIA required | C14: =IF(C13>=2,"DPIA required","No DPIA") -> DPIA required | D14: =IF(D13>=2,"DPIA required","No DPIA") -> DPIA required

Sheet 10_Findings
A1: Part 7 - findings register AF-01 to AF-13.
A3: Finding ID | B3: Severity | C3: Title | D3: What we found | E3: Requirement | F3: Root cause | G3: Remediation | H3: Effort (S/M/L) | I3: Owner (job title) | J3: Due | K3: Roadmap link | L3: Risk ID | M3: AI systems | N3: Status
A4: AF-01 | B4: Critical | C4: ScribeCo records customer calls with no contract of any kind | D4: AIS-01 joins internal and customer calls and stores audio and transcripts in the United States. There is no contract, DPA or transfer mechanism. CGI-TPR-001 set a decision for 15 Oct 2026; none is recorded. | E4: GDPR Arts 28 and 44-46; CGI-TPR-001 Gate B (no DPA, no onboarding); CGI-POL-001 s4.5.1-4.5.2 | F4: Bought on a personal card; never entered onboarding; the decision date passed without an owner chasing it. | G4: Today: remove the bot from all calls. By 24 Oct: CEO decides contract (DPA, no training, no human review, transfer mechanism, 30-day retention, deletion on exit) or exit with a deletion certificate. Record a nonconformity against CGI-POL-001 s4.5. | H4: S | I4: Head of Customer Success | J4: 24 Oct 2026 | K4: AIG-01 | L4: VR-001; VR-005; VR-006; R-003 | M4: AIS-01 | N4: Open
A5: AF-02 | B5: High | C5: ChatCo's AI reads customer content under no training prohibition, and the switch-off is unevidenced | D5: F-004 (15 Sep 2026): AI features process message content, including customers' posts in 3 shared channels; training not prohibited, human review not excluded. Action R4 (switch off by 01 Oct 2026) has no completion evidence. | E5: VQ-68, VQ-69 (weight 5); GDPR Art. 28 | F5: AI terms not read at procurement; R4 had no evidence requirement checked. | G5: Screenshot the admin setting showing AI off (today). Keep off until the DPA includes no-training and no-human-review clauses (ISO-09). | H5: S | I5: Chief Technology Officer | J5: 24 Oct 2026 | K5: AIG-02 | L5: VR-006; VR-001 | M5: AIS-02 | N5: Open
A6: AF-03 | B6: Medium | C6: The approved AI tools list the policy depends on does not exist | D6: CGI-POL-001 s4.5.1 tells staff to use only tools on the CTO's approved list. No list is recorded anywhere, so staff cannot comply and nobody can check. | E6: CGI-POL-001 s4.5.1; ISO/IEC 42001 A.9.2, A.4.2 | F6: The policy clause was approved before the list was built. | G6: Publish list v1 (WriteCo with conditions; ScribeCo and ChatCo AI pending) and adopt the AI register from Part 2 as its record. | H6: S | I6: Chief Technology Officer | J6: 31 Oct 2026 | K6: AIG-03 | L6: VR-005 | M6: AIS-01; AIS-02; AIS-03 | N6: Open
A7: AF-04 | B7: High | C7: Cypher cannot yet prove it has no prohibited or high-risk AI use | D7: VQ-67 answers are recorded for ChatCo only. AI features of HRCo, SupportCo, CRMCo, OfficeCo and the other suppliers are unconfirmed, so AI-A02 and AI-A03 are assumptions. | E7: AI Act Arts 5 and 6 with Annex III (classification needs a complete population) | F7: The AI questionnaire domain has been answered by one Tier 1 supplier. | G7: Run an AI-feature census: VQ-67 and VQ-68 to all 17 suppliers; confirm HRCo has no screening or evaluation features in use. | H7: M | I7: Chief Technology Officer | J7: 30 Nov 2026 | K7: AIG-04 | L7: VR-005; AR-002 | M7: All | N7: Open
A8: AF-05 | B8: Medium | C8: AI literacy measures cover 60% of staff and say nothing specific about AI | D8: CGI-POL-001 (with s4.5) is acknowledged by 60% of staff. No AI-use module exists (OFI-04). Some measure exists, so the Art. 4 duty is partly met, not unmet. | E8: AI Act Art. 4 (take measures to support AI literacy; since 2 Feb 2025, rewritten 27 Jul 2026) | F8: Awareness is induction-only (CG-04). | G8: AI-use module for every staff member who uses AIS-01 to AIS-03, with a completion record; pulled forward from REC-09. | H8: S | I8: Head of People and Operations | J8: 31 Dec 2026 | K8: AIG-08 | L8: VR-005; VR-006; AR-001 | M8: AIS-01; AIS-02; AIS-03 | N8: Open
A9: AF-06 | B9: Medium | C9: No record that AI output is checked before it reaches a customer | D9: CGI-POL-001 s4.5.3 requires a competent person to review AI output before it is sent to a customer. No review record or reviewer exists, and nobody has tested ScribeCo's accuracy. | E9: CGI-POL-001 s4.5.3; ISO/IEC 42001 A.6.2.4, A.6.2.6, A.9.2 | F9: Rule written; no procedure or record behind it. | G9: Named reviewers per tool; review step and log; monthly sample of 10 summaries checked against recordings. | H9: M | I9: Head of Customer Success | J9: 31 Jan 2027 | K9: AIG-09 | L9: AR-001 | M9: AIS-01; AIS-03 | N9: Open
A10: AF-07 | B10: High | C10: No DPIA was done for three AI tools that meet the DPIA criteria | D10: Screening against the nine EDPB criteria: ScribeCo meets 4, ChatCo AI 3, WriteCo 3. Two or more usually means a DPIA is required. None has one. | E10: GDPR Art. 35; ISO/IEC 42001 6.1.4, 8.4, A.5.2-A.5.4 | F10: No impact-assessment trigger in onboarding. | G10: DPIA for ScribeCo before any further use, and for ChatCo AI before re-enabling; WriteCo by 30 Nov. Add the trigger to CGI-TPR-001. | H10: M | I10: Chief Technology Officer | J10: 30 Nov 2026 | K10: AIG-05 | L10: VR-006; VR-001 | M10: AIS-01; AIS-02; AIS-03 | N10: Open
A11: AF-08 | B11: Medium | C11: No AI policy, AIMS scope or AI roles | D11: The only AI rules are four clauses in CGI-POL-001 s4.5. Nobody owns AI governance. | E11: ISO/IEC 42001 4.3, 5.2, 5.3; A.2.2, A.3.2 | F11: AI arrived through suppliers before anyone planned for it. | G11: AI policy v1.0 (extends s4.5; banned uses; impact-assessment rule), AIMS scope statement and AI roles in the ISO-04 RACI. | H11: M | I11: Chief Executive Officer | J11: 31 Dec 2026 | K11: AIG-07 | L11: VR-005; VR-006; AR-002 | M11: All | N11: Open
A12: AF-09 | B12: High | C12: People on recorded calls are not told | D12: Customers and staff on ScribeCo calls, and customers in ChatCo shared channels, are not told their words are processed by a third-party AI. | E12: GDPR Arts 13-14; ISO/IEC 42001 A.8.5 | F12: Tools arrived outside any process that writes notices. | G12: Spoken and written notice on every recorded call; channel notice; AI sub-processors added to the customer-facing list. | H12: S | I12: Head of Customer Success | J12: 30 Nov 2026 | K12: AIG-06 | L12: VR-006 | M12: AIS-01; AIS-02 | N12: Open
A13: AF-10 | B13: Medium | C13: No route to report a harmful or wrong AI output | D13: CGI-POL-005 covers security incidents. Nothing tells staff or customers how to report a wrong summary or misuse of an AI tool. | E13: ISO/IEC 42001 A.3.3, A.8.3, A.8.4 | F13: AI harms were never treated as incidents. | G13: Add an 'AI output or misuse' category to CGI-POL-005 reporting, and a customer contact route. | H13: S | I13: Chief Technology Officer | J13: 31 Jan 2027 | K13: AIG-10 | L13: AR-001 | M13: All | N13: Open
A14: AF-11 | B14: Medium | C14: Nothing stops an approved tool being used for a banned or high-risk purpose | D14: Onboarding controls new tools, not new uses. HR could use WriteCo to rank applicants (Annex III 4(a), and Art. 25(1)(c) would make Cypher the provider) or switch on voice emotion analysis (Art. 5(1)(f)). | E14: AI Act Arts 5, 6(2) and Annex III, 25(1)(c); ISO/IEC 42001 A.9.4 | F14: Use is assessed at purchase, never afterwards. | G14: Banned-use list in the AI policy; intended use recorded per tool in the register; HR sign-off for any AI touching staff decisions. | H14: S | I14: Chief Executive Officer | J14: 31 Dec 2026 | K14: AIG-07 | L14: AR-002 | M14: All | N14: Open
... A16: AF-13 | B16: Medium | C16: Scenario AI-A01: no design gate for Cypher's first AI product feature | D16: The planned project assistant would make Cypher a provider with Art. 50 duties at launch. No intended-purpose statement, design controls (A.6, A.7) or supplier assessment of ModelCo exists, and CGI-POL-007 (secure development) is not yet written. | E16: AI Act Arts 3(3), 50(1)-(2), 6(2) and Annex III 4(b); ISO/IEC 42001 A.6, A.7, A.5 | F16: Product planning ahead of governance (scenario). | G16: Design gate before any build: intended-purpose statement excluding staff evaluation; Art. 50 design requirements; impact assessment; ModelCo assessed as Tier 1 under CGI-TPR-001. | H16: M | I16: Chief Technology Officer | J16: 31 Mar 2027 | K16: AIG-13 | L16: R-004; AR-002 | M16: AIS-04 | N16: Open (scenario)
A18: Critical | B18: =COUNTIF(B4:B16,"Critical") -> 1
A19: High | B19: =COUNTIF(B4:B16,"High") -> 4
A20: Medium | B20: =COUNTIF(B4:B16,"Medium") -> 7
A21: Low | B21: =COUNTIF(B4:B16,"Low") -> 1
A22: Total | B22: =SUM(B18:B21) -> 13

Sheet 11_Severity_Rule
A1: Part 7.1 - severity rule, published before any finding was graded.
A3: Severity | B3: Rule
A4: Critical | B4: Customer or personal data is processed by an AI system today under no contract of any kind, or a prohibited practice (Art. 5) is in use.
A5: High | B5: A legal duty in force today is unmet (GDPR Arts 13-14, 28, 35; AI Act Art. 4 with no measure at all), or customer content sits under no training or human-review prohibition, or Cypher cannot tell whether it has a prohibited or high-risk use.
A6: Medium | B6: An approved policy control or a required management-system process is absent or unevidenced, with no legal duty unmet today.
A7: Low | B7: A documentation or customer-assurance gap with no exposure.

Sheet 12_Mapping
A1: Part 6 - each finding across seven frameworks. 'None' is stated where no counterpart exists.
A3: Finding ID | B3: Severity | C3: EU AI Act | D3: ISO/IEC 42001 | E3: ISO/IEC 27001:2022 Annex A | F3: SOC 2 (TSC) | G3: NIST CSF 2.0 | H3: NIST AI RMF | I3: Risk ID
A4: AF-01 | B4: Critical | C4: None directly (Art. 4 only). The duty broken is GDPR Arts 28 and 44-46 | D4: A.10.2; A.10.3; 8.1 | E4: A.5.19; A.5.20; A.5.34 | F4: CC9.2 | G4: GV.SC | H4: GOVERN | I4: VR-001; VR-005; VR-006; R-003
A5: AF-02 | B5: High | C5: None (ChatCo holds the provider duties). GDPR Art. 28 | D5: A.10.2; A.10.3 | E5: A.5.20; A.5.34 | F5: CC9.2 | G5: GV.SC; PR.DS | H5: GOVERN; MAP | I5: VR-006; VR-001
A6: AF-03 | B6: Medium | C6: Art. 4 (a measure staff can follow) | D6: A.9.2; A.4.2; A.6.2.5; 8.1 | E6: A.5.10; A.5.9 | F6: CC5.3 | G6: GV.PO; ID.AM | H6: GOVERN; MAP | I6: VR-005
A7: AF-04 | B7: High | C7: Art. 5; Art. 6(2) and Annex III | D7: 4.1; A.4.2; A.10.3 | E7: A.5.9; A.5.31 | F7: None: CGI-SOC-001 found A.5.31 has no criterion counterpart | G7: ID.AM; GV.OC | H7: MAP | I7: VR-005; AR-002
A8: AF-05 | B8: Medium | C8: Art. 4 | D8: 7.2; 7.3; A.4.6; A.8.2 | E8: A.6.3 | F8: CC1.4; CC2.2 | G8: PR.AT | H8: GOVERN | I8: VR-005; VR-006; AR-001
A9: AF-06 | B9: Medium | C9: None: Arts 14 and 26 apply to high-risk systems only. Voluntary alignment | D9: A.6.2.4; A.6.2.6; A.9.2 | E9: None: Annex A has no control for output accuracy (nearest A.5.10) | F9: None in scope: Processing Integrity is outside Cypher's SOC 2 scope | G9: None: CSF 2.0 has no Category for output accuracy (nearest GV.PO) | H9: MEASURE; MANAGE | I9: AR-001
A10: AF-07 | B10: High | C10: None for Cypher (Art. 27 FRIA applies only to certain deployers of high-risk systems). GDPR Art. 35 | D10: 6.1.4; 8.4; A.5.2; A.5.3; A.5.4 | E10: A.5.34 | F10: None: Privacy is outside Cypher's SOC 2 scope (SOC-A03) | G10: ID.RA; GV.OC | H10: MAP | I10: VR-006; VR-001
A11: AF-08 | B11: Medium | C11: Art. 4 (measures need an owner) | D11: 4.3; 5.2; 5.3; A.2.2; A.3.2 | E11: A.5.1; A.5.2 | F11: CC1.3; CC5.3 | G11: GV.PO; GV.RR | H11: GOVERN | I11: VR-005; VR-006; AR-002
A12: AF-09 | B12: High | C12: None for Cypher as deployer (Art. 50(3)-(4) not triggered). GDPR Arts 13-14 | D12: A.8.5; A.10.4 | E12: A.5.34 | F12: CC2.3 | G12: GV.OC | H12: GOVERN; MAP | I12: VR-006
A13: AF-10 | B13: Medium | C13: None directly | D13: A.3.3; A.8.3; A.8.4 | E13: A.5.24; A.6.8 | F13: CC2.3; CC7.3 | G13: RS.MA; RS.CO | H13: MANAGE | I13: AR-001
A14: AF-11 | B14: Medium | C14: Art. 5(1)(f); Art. 6(2) and Annex III point 4; Art. 25(1)(c) | D14: A.9.4; A.2.2 | E14: A.5.31 | F14: None: CGI-SOC-001 found A.5.31 has no criterion counterpart | G14: GV.OC | H14: GOVERN; MAP | I14: AR-002
... A16: AF-13 | B16: Medium | C16: Art. 3(3); Art. 50(1)-(2); Art. 6(2) and Annex III 4(b); Art. 4 | D16: A.6.1.2; A.6.1.3; A.6.2.2; A.5.2; A.8.2 | E16: A.5.8; A.8.25; A.8.26 | F16: CC3.4; CC8.1 | G16: GV.OC; ID.RA | H16: MAP; MEASURE | I16: R-004; AR-002

Sheet 13_Drawer2_Test
A1: Part 8.1 - would the existing risk's controls have prevented it? If not, it is a new risk.
A3: Candidate event | B3: Existing risk considered | C3: Would its controls have prevented it? | D3: Decision
A4: ScribeCo processes customer call audio under no contract | B4: VR-001 | C4: Yes: Gate B (no DPA, no onboarding) stops exactly this | D4: Existing risk, new route: VR-001 already lists CGI-VEN-012. No new risk
A5: A supplier trains on or reviews Cypher's content | B5: VR-006 | C5: Yes: it is VR-006's own scenario | D5: Existing risk. No new risk
A6: A team adopts an AI tool with no review | B6: VR-005 | C6: Yes, when the tool is paid for or connected | D6: Existing risk. No new risk
A7: Staff paste Confidential data into a free web AI tool | B7: VR-005 | C7: No: expense and OAuth reconciliation cannot see a free browser tool, though VR-005's scenario names free tiers | D7: Existing risk, control gap: flag VR-005's residual for the Q1 2027 review (same treatment as R-001 in CGI-AWS-001). No new risk
A8: Inaccurate AI output is acted on or sent to a customer | B8: VR-006; VR-005 | C8: No: neither control set touches output accuracy | D8: NEW RISK AR-001
A9: An approved tool is used for a prohibited or Annex III purpose | B9: VR-005 | C9: No: the gate checks tools at purchase, not later uses | D9: NEW RISK AR-002

Sheet 14_Register_v1.3
A1: Part 8 - CGI-RSK-001 v1.3: 14 risks from v1.2 plus AR-001 and AR-002. Scores are formulas.
