Workbook

Sheet 00_README
A1: Vendor Security Questionnaire — scoring template
A2: REUSABLE TEMPLATE. Replace the organisation details, choose the tier on the Scoring sheet, and record a verdict for every applicable question. Prepared by Olugboye Shola.
A4: How it scores | B4: Deduction = full weight for every Not Met + half the weight for every Partial. N/A questions leave the maximum. Score = 1 − deduction ÷ maximum.
A5: The veto | B5: Two or more weight-5 questions marked Not Met force a Fail, whatever the percentage.
A6: Tier subsets | B6: Tier 1 = all 74 questions · Tier 2 = the 24 weight-5 questions · Tier 3 = six fixed attestation questions.
A8: SHEETS
A9: Scoring | B9: Choose the tier in the yellow cell. Every result is a formula.
A10: Questionnaire | B10: The 74 questions. Fill Vendor Response, Evidence Provided and Reviewer Verdict. "Applies" is calculated from the tier.
A12: COLOUR LEGEND
A13: Yellow cell | B13: Input — type or choose here
A14: Grey cell | B14: Formula — do not overwrite
A15: Green | B15: Pass / compliant / low
A16: Amber | B16: Partial / condition / medium
A17: Red | B17: Fail / non-compliant / high or critical
A19: PUBLISHING
A20: GitHub | B20: Upload this .xlsx next to its .md file. GitHub cannot preview .xlsx, so the project README links to it as a download.
A21: Notion | B21: Import the matching CSV files from the data/ folder (Settings → Import → CSV) for sortable databases.

Sheet Scoring
A1: [ORGANISATION] — Vendor assessment scoring
A2: Replace the bracketed fields. Grey cells are formulas.
A3: Item | B3: Value
A4: Vendor | B4: [VENDOR NAME — VEN-nnn]
A5: Tier (1, 2 or 3) | B5: 1
A6: Questions applied | B6: =SUM(Questionnaire!$L$2:$L$75) -> 74
A7: Questions answered | B7: =SUMPRODUCT(Questionnaire!$L$2:$L$75*(Questionnaire!$O$2:$O$75<>"")) -> 0
A8: Met | B8: =SUMPRODUCT(Questionnaire!$L$2:$L$75*(Questionnaire!$O$2:$O$75="Met")) -> 0
A9: Partial | B9: =SUMPRODUCT(Questionnaire!$L$2:$L$75*(Questionnaire!$O$2:$O$75="Partial")) -> 0
A10: Not Met | B10: =SUMPRODUCT(Questionnaire!$L$2:$L$75*(Questionnaire!$O$2:$O$75="Not Met")) -> 0
A11: N/A | B11: =SUMPRODUCT(Questionnaire!$L$2:$L$75*(Questionnaire!$O$2:$O$75="N/A")) -> 0
A12: Maximum (applied weight, net of N/A) | B12: =SUMPRODUCT(Questionnaire!$L$2:$L$75*Questionnaire!$F$2:$F$75*(Questionnaire!$O$2:$O$75<>"N/A")) -> 288
A13: Weighted deduction | B13: =SUMPRODUCT(Questionnaire!$L$2:$L$75*Questionnaire!$F$2:$F$75*(Questionnaire!$O$2:$O$75="Not Met"))+0.5*SUMPRODUCT(Questionnaire!$L$2:$L$75*Questionnaire!$F$2:$F$75*(Questionnaire!$O$2:$O$75="Partial")) -> 0
A14: Weighted score | B14: =IF(OR(B12=0,B7=0),"",1-B13/B12)
A15: Weight-5 questions Not Met | B15: =SUMPRODUCT(Questionnaire!$L$2:$L$75*(Questionnaire!$F$2:$F$75=5)*(Questionnaire!$O$2:$O$75="Not Met")) -> 0
A16: Scoring band | B16: =IF(B7<B6,"Incomplete — "&(B6-B7)&" questions unanswered",IF(OR(B14<0.75,B15>=2),"Fail",IF(OR(B14<0.9,B15=1),"Pass with conditions",IF(B5=3,"Pass — may be accepted with justification","Pass")))) -> Incomplete — 74 questions unanswered

Sheet Questionnaire
A1: Question ID | B1: Domain | C1: Question | D1: Response Type | E1: Evidence Required | F1: Risk Weight (1-5) | G1: ISO/IEC 27001:2022 Annex A | H1: NIST CSF 2.0 | I1: Tier 1 | J1: Tier 2 (Lite) | K1: Tier 3 (Attestation) | L1: Applies (1/0) | M1: Vendor Response | N1: Evidence Provided (Y/N) | O1: Reviewer Verdict (Met/Partial/Not Met/N/A) | P1: Finding ID | Q1: Reviewer Comment
A2: VQ-01 | B2: 1. Governance and Security Programme | C2: Do you maintain a documented information security programme formally approved by executive management? | D2: Yes/No + document | E2: Approved security policy set with an approval record | F2: 4 | G2: A.5.1, A.5.4 | H2: GV.PO | I2: Y | J2: =IF(F2=5,"Y","") | L2: =IF(Scoring!$B$5=1,1,IF(Scoring!$B$5=2,IF(J2="Y",1,0),IF(K2="Y",1,0))) -> 1
A3: VQ-02 | B3: 1. Governance and Security Programme | C3: Is a named individual accountable for information security (CISO or equivalent)? State the role title. | D3: Yes/No + free text | E3: Organisation chart or role description | F3: 3 | G3: A.5.2 | H3: GV.RR | I3: Y | J3: =IF(F3=5,"Y","") | L3: =IF(Scoring!$B$5=1,1,IF(Scoring!$B$5=2,IF(J3="Y",1,0),IF(K3="Y",1,0))) -> 1
A4: VQ-03 | B4: 1. Governance and Security Programme | C4: How many staff are dedicated to information security on a full-time basis? | D4: Numeric | E4: Written headcount statement | F4: 2 | G4: A.5.2 | H4: GV.RR | I4: Y | J4: =IF(F4=5,"Y","") | L4: =IF(Scoring!$B$5=1,1,IF(Scoring!$B$5=2,IF(J4="Y",1,0),IF(K4="Y",1,0))) -> 1
A5: VQ-04 | B5: 1. Governance and Security Programme | C5: Are security policies reviewed at least annually? State the date of the last review. | D5: Yes/No + date | E5: Dated review or approval record | F5: 3 | G5: A.5.1, A.5.36 | H5: GV.PO | I5: Y | J5: =IF(F5=5,"Y","") | L5: =IF(Scoring!$B$5=1,1,IF(Scoring!$B$5=2,IF(J5="Y",1,0),IF(K5="Y",1,0))) -> 1
A6: VQ-05 | B6: 1. Governance and Security Programme | C6: Do you report security performance metrics to executive management at least quarterly? | D6: Yes/No | E6: Redacted sample management report | F6: 2 | G6: A.5.35 | H6: GV.OV | I6: Y | J6: =IF(F6=5,"Y","") | L6: =IF(Scoring!$B$5=1,1,IF(Scoring!$B$5=2,IF(J6="Y",1,0),IF(K6="Y",1,0))) -> 1
A7: VQ-06 | B7: 2. Risk Management | C7: Do you operate a documented information security risk assessment methodology? | D7: Yes/No + document | E7: Methodology document naming the scoring method | F7: 4 | G7: A.5.1 | H7: ID.RA | I7: Y | J7: =IF(F7=5,"Y","") | L7: =IF(Scoring!$B$5=1,1,IF(Scoring!$B$5=2,IF(J7="Y",1,0),IF(K7="Y",1,0))) -> 1
A8: VQ-07 | B8: 2. Risk Management | C8: When was your last enterprise information security risk assessment completed? | D8: Date | E8: Assessment summary or management report | F8: 3 | G8: A.5.1 | H8: ID.RA | I8: Y | J8: =IF(F8=5,"Y","") | L8: =IF(Scoring!$B$5=1,1,IF(Scoring!$B$5=2,IF(J8="Y",1,0),IF(K8="Y",1,0))) -> 1
A9: VQ-08 | B9: 2. Risk Management | C9: Is there a documented risk acceptance process with a defined approval authority? | D9: Yes/No | E9: Sample risk acceptance record | F9: 3 | G9: A.5.4 | H9: GV.RM | I9: Y | J9: =IF(F9=5,"Y","") | L9: =IF(Scoring!$B$5=1,1,IF(Scoring!$B$5=2,IF(J9="Y",1,0),IF(K9="Y",1,0))) -> 1
A10: VQ-09 | B10: 2. Risk Management | C10: Does your risk register include risks arising from your own suppliers? | D10: Yes/No | E10: Redacted register extract | F10: 3 | G10: A.5.21 | H10: GV.SC | I10: Y | J10: =IF(F10=5,"Y","") | L10: =IF(Scoring!$B$5=1,1,IF(Scoring!$B$5=2,IF(J10="Y",1,0),IF(K10="Y",1,0))) -> 1
A11: VQ-10 | B11: 3. Policies, Compliance and Certifications | C11: Do you hold a current ISO/IEC 27001 certificate issued by an accredited certification body? | D11: Yes/No/NA + upload | E11: Certificate showing certification body and accreditation mark | F11: 5 | G11: A.5.1, A.5.31 | H11: GV.OC | I11: Y | J11: =IF(F11=5,"Y","") -> Y | L11: =IF(Scoring!$B$5=1,1,IF(Scoring!$B$5=2,IF(J11="Y",1,0),IF(K11="Y",1,0))) -> 1
A12: VQ-11 | B12: 3. Policies, Compliance and Certifications | C12: State the exact scope of that certificate, transcribed as written on the certificate itself. | D12: Free text | E12: Certificate scope statement | F12: 5 | G12: A.5.1, A.5.31 | H12: GV.OC | I12: Y | J12: =IF(F12=5,"Y","") -> Y | L12: =IF(Scoring!$B$5=1,1,IF(Scoring!$B$5=2,IF(J12="Y",1,0),IF(K12="Y",1,0))) -> 1
A13: VQ-12 | B13: 3. Policies, Compliance and Certifications | C13: Do you provide a SOC 2 Type II report, and what period does it cover? | D13: Yes/No + date range + upload | E13: Complete report including Section 4 test results | F13: 5 | G13: A.5.1, A.5.31 | H13: GV.OC | I13: Y | J13: =IF(F13=5,"Y","") -> Y | K13: Y | L13: =IF(Scoring!$B$5=1,1,IF(Scoring!$B$5=2,IF(J13="Y",1,0),IF(K13="Y",1,0))) -> 1
A14: VQ-13 | B14: 3. Policies, Compliance and Certifications | C14: Does that report use the CARVE-OUT or the INCLUSIVE method for sub-service organisations? Name every carved-out sub-service organisation. | D14: Multiple choice + free text | E14: Report Section 3 system description | F14: 5 | G14: A.5.21, A.5.23 | H14: GV.SC | I14: Y | J14: =IF(F14=5,"Y","") -> Y | L14: =IF(Scoring!$B$5=1,1,IF(Scoring!$B$5=2,IF(J14="Y",1,0),IF(K14="Y",1,0))) -> 1
A15: VQ-14 | B15: 3. Policies, Compliance and Certifications | C15: List every exception, qualification or deviation in your most recent report, and its remediation status. | D15: Free text | E15: Report Section 4 plus written remediation plan | F15: 5 | G15: A.5.36 | H15: GV.OV | I15: Y | J15: =IF(F15=5,"Y","") -> Y | L15: =IF(Scoring!$B$5=1,1,IF(Scoring!$B$5=2,IF(J15="Y",1,0),IF(K15="Y",1,0))) -> 1
A16: VQ-15 | B16: 4. Identity and Access Management | C16: Is multi-factor authentication enforced for all personnel with access to customer data? | D16: Yes/No | E16: Policy plus configuration evidence | F16: 5 | G16: A.8.5, A.5.17 | H16: PR.AA | I16: Y | J16: =IF(F16=5,"Y","") -> Y | L16: =IF(Scoring!$B$5=1,1,IF(Scoring!$B$5=2,IF(J16="Y",1,0),IF(K16="Y",1,0))) -> 1
A17: VQ-16 | B17: 4. Identity and Access Management | C17: Is phishing-resistant MFA enforced for privileged and administrative accounts? | D17: Yes/No | E17: Configuration evidence | F17: 4 | G17: A.8.2, A.8.5 | H17: PR.AA | I17: Y | J17: =IF(F17=5,"Y","") | L17: =IF(Scoring!$B$5=1,1,IF(Scoring!$B$5=2,IF(J17="Y",1,0),IF(K17="Y",1,0))) -> 1
A18: VQ-17 | B18: 4. Identity and Access Management | C18: Is access granted on a documented least-privilege, role-based model? | D18: Yes/No + document | E18: Role-based access control model | F18: 4 | G18: A.5.15, A.5.18 | H18: PR.AA | I18: Y | J18: =IF(F18=5,"Y","") | L18: =IF(Scoring!$B$5=1,1,IF(Scoring!$B$5=2,IF(J18="Y",1,0),IF(K18="Y",1,0))) -> 1
A19: VQ-18 | B19: 4. Identity and Access Management | C19: How frequently are user access rights reviewed? State the date of the last completed review. | D19: Multiple choice + date | E19: Signed and dated access review record | F19: 4 | G19: A.5.18 | H19: PR.AA | I19: Y | J19: =IF(F19=5,"Y","") | L19: =IF(Scoring!$B$5=1,1,IF(Scoring!$B$5=2,IF(J19="Y",1,0),IF(K19="Y",1,0))) -> 1
A20: VQ-19 | B20: 4. Identity and Access Management | C20: What is your service-level commitment for revoking access on employee termination? | D20: Numeric (hours) | E20: Procedure plus a sample completed revocation record | F20: 4 | G20: A.5.18, A.6.5 | H20: PR.AA | I20: Y | J20: =IF(F20=5,"Y","") | L20: =IF(Scoring!$B$5=1,1,IF(Scoring!$B$5=2,IF(J20="Y",1,0),IF(K20="Y",1,0))) -> 1
A21: VQ-20 | B21: 4. Identity and Access Management | C21: Do you support SSO (SAML or OIDC) and automated provisioning and deprovisioning (SCIM) for customer administrators? | D21: Yes/No | E21: Product documentation | F21: 4 | G21: A.5.16 | H21: PR.AA | I21: Y | J21: =IF(F21=5,"Y","") | L21: =IF(Scoring!$B$5=1,1,IF(Scoring!$B$5=2,IF(J21="Y",1,0),IF(K21="Y",1,0))) -> 1
A22: VQ-21 | B22: 5. Data Protection and Encryption | C22: Is customer data encrypted at rest? State the algorithm and key length. | D22: Yes/No + free text | E22: Encryption standard | F22: 5 | G22: A.8.24 | H22: PR.DS | I22: Y | J22: =IF(F22=5,"Y","") -> Y | L22: =IF(Scoring!$B$5=1,1,IF(Scoring!$B$5=2,IF(J22="Y",1,0),IF(K22="Y",1,0))) -> 1
A23: VQ-22 | B23: 5. Data Protection and Encryption | C23: Is customer data encrypted in transit? State the minimum TLS version enforced. | D23: Yes/No + free text | E23: TLS configuration evidence | F23: 5 | G23: A.8.24 | H23: PR.DS | I23: Y | J23: =IF(F23=5,"Y","") -> Y | L23: =IF(Scoring!$B$5=1,1,IF(Scoring!$B$5=2,IF(J23="Y",1,0),IF(K23="Y",1,0))) -> 1
A24: VQ-23 | B24: 5. Data Protection and Encryption | C24: How are encryption keys generated, stored and rotated? Is a customer-managed key option available? | D24: Free text | E24: Key management procedure | F24: 3 | G24: A.8.24 | H24: PR.DS | I24: Y | J24: =IF(F24=5,"Y","") | L24: =IF(Scoring!$B$5=1,1,IF(Scoring!$B$5=2,IF(J24="Y",1,0),IF(K24="Y",1,0))) -> 1
A25: VQ-24 | B25: 5. Data Protection and Encryption | C25: Is customer data logically or physically segregated between tenants? Describe the mechanism. | D25: Yes/No + free text | E25: Architecture or multi-tenancy description | F25: 5 | G25: A.8.22, A.8.31 | H25: PR.DS | I25: Y | J25: =IF(F25=5,"Y","") -> Y | L25: =IF(Scoring!$B$5=1,1,IF(Scoring!$B$5=2,IF(J25="Y",1,0),IF(K25="Y",1,0))) -> 1
... A27: VQ-26 | B27: 5. Data Protection and Encryption | C27: Do you deploy data loss prevention or egress monitoring on systems holding customer data? | D27: Yes/No | E27: DLP configuration summary | F27: 3 | G27: A.8.12 | H27: PR.DS | I27: Y | J27: =IF(F27=5,"Y","") | L27: =IF(Scoring!$B$5=1,1,IF(Scoring!$B$5=2,IF(J27="Y",1,0),IF(K27="Y",1,0))) -> 1
A28: VQ-27 | B28: 6. Data Privacy and GDPR | C28: Will you execute our Data Processing Agreement, or provide one satisfying GDPR Article 28(3)? | D28: Yes/No | E28: Executed DPA | F28: 5 | G28: A.5.34, A.5.20 | H28: GV.OC | I28: Y | J28: =IF(F28=5,"Y","") -> Y | K28: Y | L28: =IF(Scoring!$B$5=1,1,IF(Scoring!$B$5=2,IF(J28="Y",1,0),IF(K28="Y",1,0))) -> 1
A29: VQ-28 | B29: 6. Data Privacy and GDPR | C29: In which countries will our data be stored, processed and accessed from, including support access? | D29: Free text | E29: Data residency statement | F29: 5 | G29: A.5.34 | H29: GV.OC | I29: Y | J29: =IF(F29=5,"Y","") -> Y | K29: Y | L29: =IF(Scoring!$B$5=1,1,IF(Scoring!$B$5=2,IF(J29="Y",1,0),IF(K29="Y",1,0))) -> 1
A30: VQ-29 | B30: 6. Data Privacy and GDPR | C30: Where data leaves the EEA, which GDPR Article 46 transfer mechanism applies? | D30: Multiple choice + free text | E30: Standard Contractual Clauses or adequacy reference, plus transfer impact assessment | F30: 5 | G30: A.5.34 | H30: GV.OC | I30: Y | J30: =IF(F30=5,"Y","") -> Y | L30: =IF(Scoring!$B$5=1,1,IF(Scoring!$B$5=2,IF(J30="Y",1,0),IF(K30="Y",1,0))) -> 1
A31: VQ-30 | B31: 6. Data Privacy and GDPR | C31: Have you appointed a Data Protection Officer or equivalent? Give the contact route. | D31: Yes/No + free text | E31: Appointment record | F31: 2 | G31: A.5.34 | H31: GV.RR | I31: Y | J31: =IF(F31=5,"Y","") | L31: =IF(Scoring!$B$5=1,1,IF(Scoring!$B$5=2,IF(J31="Y",1,0),IF(K31="Y",1,0))) -> 1
A32: VQ-31 | B32: 6. Data Privacy and GDPR | C32: Can you support data subject access, rectification and erasure requests, and within what period? | D32: Yes/No + numeric (days) | E32: Data subject request procedure | F32: 4 | G32: A.5.34 | H32: GV.OC | I32: Y | J32: =IF(F32=5,"Y","") | L32: =IF(Scoring!$B$5=1,1,IF(Scoring!$B$5=2,IF(J32="Y",1,0),IF(K32="Y",1,0))) -> 1
A33: VQ-32 | B33: 6. Data Privacy and GDPR | C33: Do you maintain records of processing activities under GDPR Article 30? | D33: Yes/No | E33: Records of processing extract | F33: 3 | G33: A.5.34 | H33: GV.OC | I33: Y | J33: =IF(F33=5,"Y","") | L33: =IF(Scoring!$B$5=1,1,IF(Scoring!$B$5=2,IF(J33="Y",1,0),IF(K33="Y",1,0))) -> 1
A34: VQ-33 | B34: 7. Sub-processors and Fourth Parties | C34: Provide your complete current sub-processor list, with the service each performs and its location. | D34: Free text + upload | E34: Published or contractual sub-processor register | F34: 5 | G34: A.5.19, A.5.21 | H34: GV.SC | I34: Y | J34: =IF(F34=5,"Y","") -> Y | L34: =IF(Scoring!$B$5=1,1,IF(Scoring!$B$5=2,IF(J34="Y",1,0),IF(K34="Y",1,0))) -> 1
A35: VQ-34 | B35: 7. Sub-processors and Fourth Parties | C35: How much prior notice is given of a new or changed sub-processor, and do we have a right to object? | D35: Numeric (days) + Yes/No | E35: Contract clause | F35: 5 | G35: A.5.22 | H35: GV.SC | I35: Y | J35: =IF(F35=5,"Y","") -> Y | L35: =IF(Scoring!$B$5=1,1,IF(Scoring!$B$5=2,IF(J35="Y",1,0),IF(K35="Y",1,0))) -> 1
A36: VQ-35 | B36: 7. Sub-processors and Fourth Parties | C36: Do you security-assess your own sub-processors before engagement? To what standard? | D36: Yes/No + free text | E36: Supplier assessment procedure | F36: 4 | G36: A.5.19, A.5.21 | H36: GV.SC | I36: Y | J36: =IF(F36=5,"Y","") | L36: =IF(Scoring!$B$5=1,1,IF(Scoring!$B$5=2,IF(J36="Y",1,0),IF(K36="Y",1,0))) -> 1
A37: VQ-36 | B37: 7. Sub-processors and Fourth Parties | C37: Do you flow down equivalent security and privacy obligations to your sub-processors? | D37: Yes/No | E37: Template sub-processor agreement | F37: 4 | G37: A.5.20 | H37: GV.SC | I37: Y | J37: =IF(F37=5,"Y","") | L37: =IF(Scoring!$B$5=1,1,IF(Scoring!$B$5=2,IF(J37="Y",1,0),IF(K37="Y",1,0))) -> 1
A38: VQ-37 | B38: 8. Secure Development and Change Management | C38: Do you follow a documented secure development lifecycle? | D38: Yes/No + document | E38: SDLC procedure | F38: 4 | G38: A.8.25 | H38: PR.PS | I38: Y | J38: =IF(F38=5,"Y","") | L38: =IF(Scoring!$B$5=1,1,IF(Scoring!$B$5=2,IF(J38="Y",1,0),IF(K38="Y",1,0))) -> 1
A39: VQ-38 | B39: 8. Secure Development and Change Management | C39: Is peer code review mandatory before any merge to a production branch? | D39: Yes/No | E39: Branch protection configuration evidence | F39: 4 | G39: A.8.28, A.8.32 | H39: PR.PS | I39: Y | J39: =IF(F39=5,"Y","") | L39: =IF(Scoring!$B$5=1,1,IF(Scoring!$B$5=2,IF(J39="Y",1,0),IF(K39="Y",1,0))) -> 1
A40: VQ-39 | B40: 8. Secure Development and Change Management | C40: Are development, test and production environments separated? Is production data ever used in lower environments? | D40: Yes/No + free text | E40: Environment separation policy | F40: 4 | G40: A.8.31 | H40: PR.PS | I40: Y | J40: =IF(F40=5,"Y","") | L40: =IF(Scoring!$B$5=1,1,IF(Scoring!$B$5=2,IF(J40="Y",1,0),IF(K40="Y",1,0))) -> 1
A41: VQ-40 | B41: 8. Secure Development and Change Management | C41: Do you perform static and dynamic application security testing within the pipeline? | D41: Yes/No + free text | E41: Scan configuration and redacted sample output | F41: 4 | G41: A.8.29 | H41: PR.PS | I41: Y | J41: =IF(F41=5,"Y","") | L41: =IF(Scoring!$B$5=1,1,IF(Scoring!$B$5=2,IF(J41="Y",1,0),IF(K41="Y",1,0))) -> 1
...
